<?xml version="1.0"?>
<!-- gen_tracked_bot.py 로 생성  |  배율 k = 1.0
     차체 0.350 x 0.250 x 0.100 m  |  질량 2.00 kg
     트랙간격 0.250 m  |  구동륜지름 0.100 m  |  라이다 지상 0.200 m -->
<robot name="tracked_bot">

  <material name="body_gray">  <color rgba="0.30 0.32 0.35 1.0"/></material>
  <material name="track_black"><color rgba="0.10 0.10 0.10 1.0"/></material>
  <material name="wheel_dark"> <color rgba="0.05 0.05 0.05 1.0"/></material>
  <material name="sensor_blue"><color rgba="0.10 0.30 0.70 1.0"/></material>

  <link name="base_footprint"/>

  <joint name="base_joint" type="fixed">
    <parent link="base_footprint"/>
    <child  link="base_link"/>
    <origin xyz="0 0 0.1000" rpy="0 0 0"/>
  </joint>

  <link name="base_link">
    <visual>
      <geometry><box size="0.3500 0.2500 0.1000"/></geometry>
      <material name="body_gray"/>
    </visual>
    <collision>
      <geometry><box size="0.3500 0.2500 0.1000"/></geometry>
    </collision>
    <inertial>
      <mass value="2.0000"/>
      <inertia ixx="0.012083" ixy="0.0" ixz="0.0"
               iyy="0.022083" iyz="0.0" izz="0.030833"/>
    </inertial>
  </link>

  <joint name="track_left_joint" type="fixed">
    <parent link="base_link"/>
    <child  link="track_left_link"/>
    <origin xyz="0 0.1250 -0.0500" rpy="0 0 0"/>
  </joint>
  <link name="track_left_link">
    <visual>
      <geometry><box size="0.3605 0.0500 0.1100"/></geometry>
      <material name="track_black"/>
    </visual>
    <inertial>
      <mass value="0.005"/>
      <inertia ixx="1e-7" ixy="0.0" ixz="0.0" iyy="1e-7" iyz="0.0" izz="1e-7"/>
    </inertial>
  </link>

  <joint name="track_right_joint" type="fixed">
    <parent link="base_link"/>
    <child  link="track_right_link"/>
    <origin xyz="0 -0.1250 -0.0500" rpy="0 0 0"/>
  </joint>
  <link name="track_right_link">
    <visual>
      <geometry><box size="0.3605 0.0500 0.1100"/></geometry>
      <material name="track_black"/>
    </visual>
    <inertial>
      <mass value="0.005"/>
      <inertia ixx="1e-7" ixy="0.0" ixz="0.0" iyy="1e-7" iyz="0.0" izz="1e-7"/>
    </inertial>
  </link>

  <joint name="wheel_left_front_joint" type="continuous">
    <parent link="base_link"/>
    <child  link="wheel_left_front_link"/>
    <origin xyz="0.1100 0.1250 -0.0500" rpy="-1.570796 0 0"/>
    <axis xyz="0 0 1"/>
  </joint>
  <link name="wheel_left_front_link">
    <visual>
      <geometry><cylinder length="0.0400" radius="0.0500"/></geometry>
      <material name="wheel_dark"/>
    </visual>
    <collision>
      <geometry><cylinder length="0.0400" radius="0.0500"/></geometry>
    </collision>
    <inertial>
      <mass value="0.15000"/>
      <inertia ixx="0.00011375" ixy="0.0" ixz="0.0"
               iyy="0.00011375" iyz="0.0" izz="0.00018750"/>
    </inertial>
  </link>

  <joint name="wheel_left_rear_joint" type="continuous">
    <parent link="base_link"/>
    <child  link="wheel_left_rear_link"/>
    <origin xyz="-0.1100 0.1250 -0.0500" rpy="-1.570796 0 0"/>
    <axis xyz="0 0 1"/>
  </joint>
  <link name="wheel_left_rear_link">
    <visual>
      <geometry><cylinder length="0.0400" radius="0.0500"/></geometry>
      <material name="wheel_dark"/>
    </visual>
    <collision>
      <geometry><cylinder length="0.0400" radius="0.0500"/></geometry>
    </collision>
    <inertial>
      <mass value="0.15000"/>
      <inertia ixx="0.00011375" ixy="0.0" ixz="0.0"
               iyy="0.00011375" iyz="0.0" izz="0.00018750"/>
    </inertial>
  </link>

  <joint name="wheel_right_front_joint" type="continuous">
    <parent link="base_link"/>
    <child  link="wheel_right_front_link"/>
    <origin xyz="0.1100 -0.1250 -0.0500" rpy="-1.570796 0 0"/>
    <axis xyz="0 0 1"/>
  </joint>
  <link name="wheel_right_front_link">
    <visual>
      <geometry><cylinder length="0.0400" radius="0.0500"/></geometry>
      <material name="wheel_dark"/>
    </visual>
    <collision>
      <geometry><cylinder length="0.0400" radius="0.0500"/></geometry>
    </collision>
    <inertial>
      <mass value="0.15000"/>
      <inertia ixx="0.00011375" ixy="0.0" ixz="0.0"
               iyy="0.00011375" iyz="0.0" izz="0.00018750"/>
    </inertial>
  </link>

  <joint name="wheel_right_rear_joint" type="continuous">
    <parent link="base_link"/>
    <child  link="wheel_right_rear_link"/>
    <origin xyz="-0.1100 -0.1250 -0.0500" rpy="-1.570796 0 0"/>
    <axis xyz="0 0 1"/>
  </joint>
  <link name="wheel_right_rear_link">
    <visual>
      <geometry><cylinder length="0.0400" radius="0.0500"/></geometry>
      <material name="wheel_dark"/>
    </visual>
    <collision>
      <geometry><cylinder length="0.0400" radius="0.0500"/></geometry>
    </collision>
    <inertial>
      <mass value="0.15000"/>
      <inertia ixx="0.00011375" ixy="0.0" ixz="0.0"
               iyy="0.00011375" iyz="0.0" izz="0.00018750"/>
    </inertial>
  </link>

  <joint name="scan_joint" type="fixed">
    <parent link="base_link"/>
    <child  link="base_scan"/>
    <origin xyz="0.0750 0 0.1000" rpy="0 0 0"/>
  </joint>
  <link name="base_scan">
    <visual>
      <geometry><cylinder length="0.0250" radius="0.0200"/></geometry>
      <material name="sensor_blue"/>
    </visual>
    <collision>
      <geometry><cylinder length="0.0250" radius="0.0200"/></geometry>
    </collision>
    <inertial>
      <mass value="0.05000"/>
      <inertia ixx="1e-5" ixy="0.0" ixz="0.0" iyy="1e-5" iyz="0.0" izz="1e-5"/>
    </inertial>
  </link>

  <joint name="imu_joint" type="fixed">
    <parent link="base_link"/>
    <child  link="imu_link"/>
    <origin xyz="0 0 0.0500" rpy="0 0 0"/>
  </joint>
  <link name="imu_link">
    <inertial>
      <mass value="0.01"/>
      <inertia ixx="1e-6" ixy="0.0" ixz="0.0" iyy="1e-6" iyz="0.0" izz="1e-6"/>
    </inertial>
  </link>

  <gazebo reference="base_link"><material>Gazebo/DarkGrey</material></gazebo>
  <gazebo reference="track_left_link"><material>Gazebo/Black</material></gazebo>
  <gazebo reference="track_right_link"><material>Gazebo/Black</material></gazebo>

  <gazebo reference="wheel_left_front_link">
    <mu1>1.0</mu1><mu2>0.3</mu2>
    <fdir1>1 0 0</fdir1>
    <kp>100000.0</kp><kd>5.0</kd>
    <minDepth>0.001</minDepth>
    <material>Gazebo/Black</material>
  </gazebo>

  <gazebo reference="wheel_left_rear_link">
    <mu1>1.0</mu1><mu2>0.3</mu2>
    <fdir1>1 0 0</fdir1>
    <kp>100000.0</kp><kd>5.0</kd>
    <minDepth>0.001</minDepth>
    <material>Gazebo/Black</material>
  </gazebo>

  <gazebo reference="wheel_right_front_link">
    <mu1>1.0</mu1><mu2>0.3</mu2>
    <fdir1>1 0 0</fdir1>
    <kp>100000.0</kp><kd>5.0</kd>
    <minDepth>0.001</minDepth>
    <material>Gazebo/Black</material>
  </gazebo>

  <gazebo reference="wheel_right_rear_link">
    <mu1>1.0</mu1><mu2>0.3</mu2>
    <fdir1>1 0 0</fdir1>
    <kp>100000.0</kp><kd>5.0</kd>
    <minDepth>0.001</minDepth>
    <material>Gazebo/Black</material>
  </gazebo>

  <gazebo>
    <plugin name="tracked_diff_drive" filename="libgazebo_ros_diff_drive.so">
      <ros>
        <remapping>cmd_vel:=cmd_vel</remapping>
        <remapping>odom:=odom</remapping>
      </ros>
      <update_rate>30</update_rate>
      <num_wheel_pairs>2</num_wheel_pairs>
      <left_joint>wheel_left_front_joint</left_joint>
      <left_joint>wheel_left_rear_joint</left_joint>
      <right_joint>wheel_right_front_joint</right_joint>
      <right_joint>wheel_right_rear_joint</right_joint>
      <wheel_separation>0.2500</wheel_separation>
      <wheel_separation>0.2500</wheel_separation>
      <wheel_diameter>0.1000</wheel_diameter>
      <wheel_diameter>0.1000</wheel_diameter>
      <max_wheel_torque>10.0</max_wheel_torque>
      <max_wheel_acceleration>20.0</max_wheel_acceleration>
      <publish_odom>true</publish_odom>
      <publish_odom_tf>true</publish_odom_tf>
      <publish_wheel_tf>false</publish_wheel_tf>
      <odometry_frame>odom</odometry_frame>
      <robot_base_frame>base_footprint</robot_base_frame>
    </plugin>
  </gazebo>

  <gazebo>
    <plugin name="tracked_joint_state" filename="libgazebo_ros_joint_state_publisher.so">
      <update_rate>30</update_rate>
      <joint_name>wheel_left_front_joint</joint_name>
      <joint_name>wheel_left_rear_joint</joint_name>
      <joint_name>wheel_right_front_joint</joint_name>
      <joint_name>wheel_right_rear_joint</joint_name>
    </plugin>
  </gazebo>

  <gazebo reference="base_scan">
    <material>Gazebo/FlatBlack</material>
    <sensor name="lidar_sensor" type="ray">
      <always_on>true</always_on>
      <visualize>false</visualize>
      <update_rate>10</update_rate>
      <ray>
        <scan>
          <horizontal>
            <samples>360</samples>
            <resolution>1.000000</resolution>
            <min_angle>0.000000</min_angle>
            <max_angle>6.280000</max_angle>
          </horizontal>
        </scan>
        <range>
          <min>0.1200</min>
          <max>12.0</max>
          <resolution>0.015</resolution>
        </range>
        <noise>
          <type>gaussian</type><mean>0.0</mean><stddev>0.01</stddev>
        </noise>
      </ray>
      <plugin name="lidar_plugin" filename="libgazebo_ros_ray_sensor.so">
        <ros><remapping>~/out:=scan</remapping></ros>
        <output_type>sensor_msgs/LaserScan</output_type>
        <frame_name>base_scan</frame_name>
      </plugin>
    </sensor>
  </gazebo>

  <gazebo reference="imu_link">
    <sensor name="imu_sensor" type="imu">
      <always_on>true</always_on>
      <update_rate>100</update_rate>
      <plugin name="imu_plugin" filename="libgazebo_ros_imu_sensor.so">
        <ros><remapping>~/out:=imu</remapping></ros>
        <initial_orientation_as_reference>false</initial_orientation_as_reference>
      </plugin>
    </sensor>
  </gazebo>

</robot>
